Workbook

Sheet README
A1: Moya One website: project tracker
A2: Hand this to the developer. Everything she needs to plan and report is in these tabs.
A4: How to use
A5: 1. Dashboard: enter the kickoff date in the yellow cell. All task dates recalculate from it.
A6: 2. Tracker: one row per task. Update Status (dropdown) and Notes. Do not change IDs.
A8: 4. Client Inputs: everything we are waiting on from Omar. Chase these first.
A9: 5. Claims: every factual claim for the site, and whether it can be published yet.
A13: Colour key
A14: Design audit: after every change, the developer runs the taste and impeccable skills and fixes anything that looks vibe-coded. Record "Audit: pass" in Notes. See CLAUDE.md.
A15: Yellow cell = editable input. Black text = formula, do not overwrite.
A17: Status values
A18: Not started, In progress, Blocked, Done. Mark Blocked and add the reason in Notes.
... A22: Day numbers are working days (Mon to Sat, Sunday off). Timeline: 4 weeks total (3 build, 1 test), per the call on 2026-10-22. Video is included in that window and is flagged as a risk.

Sheet Dashboard
A1: Moya One: dashboard
A3: Kickoff date (edit) | B3: 46319
A5: Status | B5: Tasks
A6: Not started | B6: =COUNTIF(Tracker!$L$2:$L$80,A6) -> 40
A7: In progress | B7: =COUNTIF(Tracker!$L$2:$L$80,A7) -> 0
A8: Blocked | B8: =COUNTIF(Tracker!$L$2:$L$80,A8) -> 0
A9: Done | B9: =COUNTIF(Tracker!$L$2:$L$80,A9) -> 0
A10: Total tasks | B10: =COUNTA(Tracker!$A$2:$A$80) -> 40
A11: Percent done | B11: =IF(B10=0,0,B9/B10) -> 0
A12: Overdue (end date passed, not Done) | B12: =COUNTIFS(Tracker!$I$2:$I$80,"<"&TODAY(),Tracker!$L$2:$L$80,"<>Done") -> 0
A13: Tasks waiting on client | B13: =COUNTIFS(Tracker!$K$2:$K$80,"Yes",Tracker!$L$2:$L$80,"<>Done") -> 12
A14: Project end date (last task) | B14: =MAX(Tracker!$I$2:$I$80) -> 46352

Sheet Tracker
A1: ID | B1: Workstream | C1: Task | D1: Owner | E1: Priority | F1: Start (working day) | G1: End (working day) | H1: Start date | I1: End date | J1: Depends on | K1: Needs client input | L1: Status | M1: Notes
A2: B1 | B2: Brand | C2: Collect logo variations (4 to 5) from client's team | D2: Vinayak | E2: Must | F2: 0 | G2: 5 | H2: =WORKDAY.INTL(Dashboard!$B$3,F2,"0000001") -> 46319 | I2: =WORKDAY.INTL(Dashboard!$B$3,G2,"0000001") -> 46325 | K2: Yes | L2: Not started | M2: Client said the logo team will send 4 to 5 options
A3: B2 | B3: Brand | C3: Collect client's colour and logo preferences | D3: Vinayak | E3: Must | F3: 0 | G3: 5 | H3: =WORKDAY.INTL(Dashboard!$B$3,F3,"0000001") -> 46319 | I3: =WORKDAY.INTL(Dashboard!$B$3,G3,"0000001") -> 46325 | K3: Yes | L3: Not started | M3: Client has no brand guidelines yet
A4: B3 | B4: Brand | C4: Lock palette (base, orange, yellow highlight, ink, grey, water blue) | D4: Vinayak | E4: Must | F4: 0 | G4: 2 | H4: =WORKDAY.INTL(Dashboard!$B$3,F4,"0000001") -> 46319 | I4: =WORKDAY.INTL(Dashboard!$B$3,G4,"0000001") -> 46322 | K4: No | L4: Not started | M4: Chosen by Vinayak. See DESIGN.md
A5: B4 | B5: Brand | C5: Lock typography and heading scale | D5: Vinayak | E5: Must | F5: 2 | G5: 4 | H5: =WORKDAY.INTL(Dashboard!$B$3,F5,"0000001") -> 46322 | I5: =WORKDAY.INTL(Dashboard!$B$3,G5,"0000001") -> 46324 | J5: B3 | K5: No | L5: Not started | M5: Build from DESIGN.md type scale
A6: B5 | B6: Brand | C6: Lock iconography set (one line weight, one style) | D6: Vinayak | E6: Must | F6: 3 | G6: 5 | H6: =WORKDAY.INTL(Dashboard!$B$3,F6,"0000001") -> 46323 | I6: =WORKDAY.INTL(Dashboard!$B$3,G6,"0000001") -> 46325 | J6: B3 | K6: No | L6: Not started | M6: Phosphor icons used in current build
A7: B6 | B7: Brand | C7: Show 2 luxury-and-convenience direction options to Rayansh | D7: Vinayak | E7: Must | F7: 2 | G7: 6 | H7: =WORKDAY.INTL(Dashboard!$B$3,F7,"0000001") -> 46322 | I7: =WORKDAY.INTL(Dashboard!$B$3,G7,"0000001") -> 46326 | J7: B4 | K7: No | L7: Not started | M7: Rayansh signs off before design work continues
A8: B7 | B8: Brand | C8: Confirm patent wording: 'patent filed', not 'patented' | D8: Rayansh | E8: Must | F8: 0 | G8: 2 | H8: =WORKDAY.INTL(Dashboard!$B$3,F8,"0000001") -> 46319 | I8: =WORKDAY.INTL(Dashboard!$B$3,G8,"0000001") -> 46322 | K8: Yes | L8: Not started | M8: Client said 'patented' but later said filed and not examined
A9: C1 | B9: Content | C9: Receive presentation PDFs and product details | D9: Omar (client) | E9: Must | F9: 0 | G9: 5 | H9: =WORKDAY.INTL(Dashboard!$B$3,F9,"0000001") -> 46319 | I9: =WORKDAY.INTL(Dashboard!$B$3,G9,"0000001") -> 46325 | K9: Yes | L9: Not started | M9: Promised by end of day 19 Oct. Chase
A10: C2 | B10: Content | C10: Receive 'How we work' document (water flow, filter stages) | D10: Omar (client) | E10: Must | F10: 0 | G10: 5 | H10: =WORKDAY.INTL(Dashboard!$B$3,F10,"0000001") -> 46319 | I10: =WORKDAY.INTL(Dashboard!$B$3,G10,"0000001") -> 46325 | K10: Yes | L10: Not started | M10: Client will share. Use only what is claimable
A11: C3 | B11: Content | C11: Verify zero water wastage and 3LD claims with client's technical team | D11: Rayansh | E11: Must | F11: 3 | G11: 10 | H11: =WORKDAY.INTL(Dashboard!$B$3,F11,"0000001") -> 46323 | I11: =WORKDAY.INTL(Dashboard!$B$3,G11,"0000001") -> 46331 | J11: C2 | K11: Yes | L11: Not started | M11: Do not publish until verified. See Claims tab
A12: C4 | B12: Content | C12: Product facts sheet: what can be said and how it is sourced | D12: Vinayak | E12: Must | F12: 5 | G12: 8 | H12: =WORKDAY.INTL(Dashboard!$B$3,F12,"0000001") -> 46325 | I12: =WORKDAY.INTL(Dashboard!$B$3,G12,"0000001") -> 46329 | J12: C2 | K12: No | L12: Not started
A13: C5 | B13: Content | C13: Write home page copy (consumer first) | D13: Rayansh | E13: Must | F13: 5 | G13: 10 | H13: =WORKDAY.INTL(Dashboard!$B$3,F13,"0000001") -> 46325 | I13: =WORKDAY.INTL(Dashboard!$B$3,G13,"0000001") -> 46331 | J13: C4 | K13: No | L13: Not started | M13: Headline: 'Get rid of the hassle.'
A14: C6 | B14: Content | C14: Write builders page copy | D14: Rayansh | E14: Must | F14: 5 | G14: 10 | H14: =WORKDAY.INTL(Dashboard!$B$3,F14,"0000001") -> 46325 | I14: =WORKDAY.INTL(Dashboard!$B$3,G14,"0000001") -> 46331 | J14: C4 | K14: No | L14: Not started
A15: C7 | B15: Content | C15: Write comparison page copy (bottles, RO filters) | D15: Rayansh | E15: Must | F15: 7 | G15: 12 | H15: =WORKDAY.INTL(Dashboard!$B$3,F15,"0000001") -> 46328 | I15: =WORKDAY.INTL(Dashboard!$B$3,G15,"0000001") -> 46333 | J15: C4 | K15: No | L15: Not started | M15: Qualitative claims only until C3 is done
A16: C8 | B16: Content | C16: Write environment page copy | D16: Rayansh | E16: Must | F16: 7 | G16: 12 | H16: =WORKDAY.INTL(Dashboard!$B$3,F16,"0000001") -> 46328 | I16: =WORKDAY.INTL(Dashboard!$B$3,G16,"0000001") -> 46333 | J16: C4 | K16: No | L16: Not started
A17: C9 | B17: Content | C17: Write contact and footer copy; replace placeholder email | D17: Rayansh | E17: Must | F17: 10 | G17: 14 | H17: =WORKDAY.INTL(Dashboard!$B$3,F17,"0000001") -> 46331 | I17: =WORKDAY.INTL(Dashboard!$B$3,G17,"0000001") -> 46336 | K17: Yes | L17: Not started | M17: Client to confirm the contact address
A18: D1 | B18: Design | C18: Moodboard: luxury and convenience reference set (5 to 8 sites) | D18: Vinayak | E18: Must | F18: 2 | G18: 5 | H18: =WORKDAY.INTL(Dashboard!$B$3,F18,"0000001") -> 46322 | I18: =WORKDAY.INTL(Dashboard!$B$3,G18,"0000001") -> 46325 | J18: B6 | K18: No | L18: Not started | M18: Avoid templates and generic SaaS look
A19: D2 | B19: Design | C19: Bottle illustration: 20-litre jug (wide body, short neck) | D19: Vinayak | E19: Must | F19: 2 | G19: 5 | H19: =WORKDAY.INTL(Dashboard!$B$3,F19,"0000001") -> 46322 | I19: =WORKDAY.INTL(Dashboard!$B$3,G19,"0000001") -> 46325 | J19: B3 | K19: No | L19: Not started | M19: Replaces the battery-shaped drawing
A20: D3 | B20: Design | C20: Hero scene: stick figure and branded dustbin | D20: Vinayak | E20: Must | F20: 6 | G20: 11 | H20: =WORKDAY.INTL(Dashboard!$B$3,F20,"0000001") -> 46326 | I20: =WORKDAY.INTL(Dashboard!$B$3,G20,"0000001") -> 46332 | J20: D2 | K20: No | L20: Not started | M20: Cap generic, dustbin Moya One branded
A21: D4 | B21: Design | C21: Basement and control room illustration (isometric, basic, no tech detail) | D21: Vinayak | E21: Must | F21: 6 | G21: 11 | H21: =WORKDAY.INTL(Dashboard!$B$3,F21,"0000001") -> 46326 | I21: =WORKDAY.INTL(Dashboard!$B$3,G21,"0000001") -> 46332 | J21: B5 | K21: No | L21: Not started | M21: Client wants more machinery; keep it evocative, not a schematic
A22: D5 | B22: Design | C22: Key screens: desktop and 390px mobile for home and builders | D22: Vinayak | E22: Must | F22: 6 | G22: 10 | H22: =WORKDAY.INTL(Dashboard!$B$3,F22,"0000001") -> 46326 | I22: =WORKDAY.INTL(Dashboard!$B$3,G22,"0000001") -> 46331 | J22: D1 | K22: No | L22: Not started
A23: D6 | B23: Design | C23: Component library: buttons, headings, cards, tables, nav | D23: Vinayak | E23: Must | F23: 8 | G23: 12 | H23: =WORKDAY.INTL(Dashboard!$B$3,F23,"0000001") -> 46329 | I23: =WORKDAY.INTL(Dashboard!$B$3,G23,"0000001") -> 46333 | J23: B4 | K23: No | L23: Not started
A24: D7 | B24: Design | C24: Client sign-off on design | D24: Omar (client) | E24: Must | F24: 12 | G24: 14 | H24: =WORKDAY.INTL(Dashboard!$B$3,F24,"0000001") -> 46333 | I24: =WORKDAY.INTL(Dashboard!$B$3,G24,"0000001") -> 46336 | J24: D5 | K24: Yes | L24: Not started | M24: Also needs Rayansh sign-off first
A25: E1 | B25: Build | C25: Project setup: framework, GSAP, Lenis, fonts, icons | D25: Harshita | E25: Must | F25: 7 | G25: 8 | H25: =WORKDAY.INTL(Dashboard!$B$3,F25,"0000001") -> 46328 | I25: =WORKDAY.INTL(Dashboard!$B$3,G25,"0000001") -> 46329 | J25: D6 | K25: No | L25: Not started | M25: Next.js, Nuxt or Vite. Developer's choice; justify it in README
A26: E2 | B26: Build | C26: Build home page (consumer first, builders teaser) | D26: Harshita | E26: Must | F26: 8 | G26: 12 | H26: =WORKDAY.INTL(Dashboard!$B$3,F26,"0000001") -> 46329 | I26: =WORKDAY.INTL(Dashboard!$B$3,G26,"0000001") -> 46333 | J26: D5 | K26: No | L26: Not started
A27: E3 | B27: Build | C27: Build builders page (with embedded MP4 video) | D27: Harshita | E27: Must | F27: 10 | G27: 13 | H27: =WORKDAY.INTL(Dashboard!$B$3,F27,"0000001") -> 46331 | I27: =WORKDAY.INTL(Dashboard!$B$3,G27,"0000001") -> 46335 | J27: E1 | K27: No | L27: Not started | M27: Video is an MP4 file, not a coded animation
A28: E4 | B28: Build | C28: Build comparison hub and comparison pages | D28: Harshita | E28: Must | F28: 10 | G28: 14 | H28: =WORKDAY.INTL(Dashboard!$B$3,F28,"0000001") -> 46331 | I28: =WORKDAY.INTL(Dashboard!$B$3,G28,"0000001") -> 46336 | J28: E1 | K28: No | L28: Not started
A29: E5 | B29: Build | C29: Build environment, technology and contact pages | D29: Harshita | E29: Must | F29: 11 | G29: 14 | H29: =WORKDAY.INTL(Dashboard!$B$3,F29,"0000001") -> 46332 | I29: =WORKDAY.INTL(Dashboard!$B$3,G29,"0000001") -> 46336 | J29: E1 | K29: No | L29: Not started
A30: E6 | B30: Build | C30: Build interactions: recharge demo, app panel, how it works | D30: Harshita | E30: Must | F30: 9 | G30: 13 | H30: =WORKDAY.INTL(Dashboard!$B$3,F30,"0000001") -> 46330 | I30: =WORKDAY.INTL(Dashboard!$B$3,G30,"0000001") -> 46335 | J30: D5 | K30: No | L30: Not started | M30: Keep numbers labelled 'sample'
A31: E7 | B31: Build | C31: Responsive QA at 390px and 1440px; no horizontal scroll | D31: Harshita | E31: Must | F31: 12 | G31: 14 | H31: =WORKDAY.INTL(Dashboard!$B$3,F31,"0000001") -> 46333 | I31: =WORKDAY.INTL(Dashboard!$B$3,G31,"0000001") -> 46336 | J31: E2 | K31: No | L31: Not started
A32: E8 | B32: Build | C32: Reduced-motion check and performance (Lighthouse mobile 85+) | D32: Harshita | E32: Must | F32: 13 | G32: 14 | H32: =WORKDAY.INTL(Dashboard!$B$3,F32,"0000001") -> 46335 | I32: =WORKDAY.INTL(Dashboard!$B$3,G32,"0000001") -> 46336 | J32: E6 | K32: No | L32: Not started
A33: F1 | B33: Video | C33: Video script and storyboard (building, pipe, kitchen unit, basement) | D33: Rayansh's team | E33: Must | F33: 0 | G33: 7 | H33: =WORKDAY.INTL(Dashboard!$B$3,F33,"0000001") -> 46319 | I33: =WORKDAY.INTL(Dashboard!$B$3,G33,"0000001") -> 46328 | K33: Yes | L33: Not started | M33: Scope split between video and website still open.
A34: F2 | B34: Video | C34: Receive client's reference animation | D34: Omar (client) | E34: Must | F34: 0 | G34: 3 | H34: =WORKDAY.INTL(Dashboard!$B$3,F34,"0000001") -> 46319 | I34: =WORKDAY.INTL(Dashboard!$B$3,G34,"0000001") -> 46323 | K34: Yes | L34: Not started | M34: Promised by end of day 22 Oct
A35: F3 | B35: Video | C35: Produce MP4 explainer (16:9, plus 9:16 cut for social) | D35: Rayansh's team | E35: Must | F35: 7 | G35: 21 | H35: =WORKDAY.INTL(Dashboard!$B$3,F35,"0000001") -> 46328 | I35: =WORKDAY.INTL(Dashboard!$B$3,G35,"0000001") -> 46344 | J35: F1 | K35: No | L35: Not started | M35: Biggest timeline risk. Confirm before kickoff
A36: F4 | B36: Video | C36: Approve video cut with client | D36: Omar (client) | E36: Must | F36: 21 | G36: 23 | H36: =WORKDAY.INTL(Dashboard!$B$3,F36,"0000001") -> 46344 | I36: =WORKDAY.INTL(Dashboard!$B$3,G36,"0000001") -> 46346 | J36: F3 | K36: Yes | L36: Not started
A37: H1 | B37: Launch | C37: Client review round 1 on full site | D37: Omar (client) | E37: Must | F37: 22 | G37: 24 | H37: =WORKDAY.INTL(Dashboard!$B$3,F37,"0000001") -> 46345 | I37: =WORKDAY.INTL(Dashboard!$B$3,G37,"0000001") -> 46347 | J37: E7 | K37: Yes | L37: Not started
A38: H2 | B38: Launch | C38: Fix review round 1 feedback | D38: Harshita | E38: Must | F38: 24 | G38: 26 | H38: =WORKDAY.INTL(Dashboard!$B$3,F38,"0000001") -> 46347 | I38: =WORKDAY.INTL(Dashboard!$B$3,G38,"0000001") -> 46350 | J38: H1 | K38: No | L38: Not started
A39: H3 | B39: Launch | C39: Hosting set up (client hosting or Socialsect server) | D39: Rayansh | E39: Must | F39: 22 | G39: 26 | H39: =WORKDAY.INTL(Dashboard!$B$3,F39,"0000001") -> 46345 | I39: =WORKDAY.INTL(Dashboard!$B$3,G39,"0000001") -> 46350 | K39: No | L39: Not started | M39: Client has no hosting yet
A40: H4 | B40: Launch | C40: Point domain DNS, go live, check SSL | D40: Harshita | E40: Must | F40: 26 | G40: 27 | H40: =WORKDAY.INTL(Dashboard!$B$3,F40,"0000001") -> 46350 | I40: =WORKDAY.INTL(Dashboard!$B$3,G40,"0000001") -> 46351 | J40: H2 | K40: No | L40: Not started
...

Sheet Sitemap
A1: Page | B1: URL (proposed) | C1: Audience | D1: Priority | E1: Purpose | F1: Status | G1: Notes
A2: Home | B2: / | C2: Consumer, then builder | D2: Phase 1 Must | E2: Hero hook, convenience, quality, teaser for builders | F2: Not started | G2: Consumer sections first; builder sections later on the same page
A3: How it works (consumer) | B3: /b2c/how-it-works | C3: Consumer | D3: Phase 1 Must | E3: Recharge, control unit in your kitchen, the flow | F3: Not started | G3: Interactive recharge demo lives here or on home
A4: Water quality | B4: /b2c/water-quality | C4: Consumer | D4: Phase 1 Should | E4: Per-flat readings: TDS, pH, alkalinity, dissolved solids | F4: Not started | G4: Sample data only until client confirms parameters
A5: Builders | B5: /b2b/builders | C5: Builder | D5: Phase 1 Must | E5: Installed at construction stage, no retrofit, space saved; embedded MP4 | F5: Not started | G5: Overview only, no technology detail
A6: Installation | B6: /b2b/installation | C6: Builder | D6: Phase 1 Should | E6: Cellar control room, pipe to each flat, what the builder provides | F6: Not started | G6: Keep basic; no schematics
A7: Compare (hub) | B7: /compare | C7: Consumer and builder | D7: Phase 1 Must | E7: Moya One vs bottled water vs RO filters | F7: Not started | G7: Qualitative labels only
A8: Compare: bottled water | B8: /compare/bottled-water | C8: Consumer and builder | D8: Phase 1 Must | E8: Bottle routine vs one pipe | F8: Not started
A9: Compare: RO filters | B9: /compare/ro-filters | C9: Consumer and builder | D9: Phase 1 Must | E9: RO wastage and maintenance vs Moya One | F9: Not started | G9: Do not state a wastage figure until verified
A10: Technology (overview) | B10: /technology | C10: Builder | D10: Phase 1 Stretch | E10: Overview of the system, patent filed, no technical depth | F10: Not started | G10: Wording per Claims tab
A11: Environment | B11: /environment | C11: Both | D11: Phase 1 Must | E11: Plastic, emissions, zero liquid discharge | F11: Not started | G11: Client asked for this page
A12: How we work | B12: /how-we-work | C12: Builder | D12: Phase 1 Should | E12: Process from installation to billing | F12: Not started | G12: Use client's 'How we work' document once received
A13: Contact | B13: /contact | C13: Both | D13: Phase 1 Must | E13: Enquiry form, developer and consumer routes | F13: Not started | G13: Form only, no login
A14: Compare: zero liquid discharge | B14: /compare/zero-liquid-discharge | C14: Both | D14: Phase 1 Stretch | E14: Water wastage angle, deeper comparison | F14: Not started | G14: Blocked until zero-wastage claim is verified
A15: Compare: other comparisons (x6) | B15: /compare/... | C15: Both | D15: Phase 1 Stretch | E15: Further comparison pages Vinayak proposed | F15: Not started | G15: Count against the 15-page scope. Confirm with Rayansh
A16: Insights / blog | B16: /insights | C16: Both | D16: Later | E16: Articles and videos | F16: Not started | G16: Deferred by client until builder handover
A17: App and login | B17: /app | C17: Consumer | D17: Later | E17: Login with payment ID and OTP, payment history | F17: Not started | G17: Not in phase 1

Sheet Client Inputs
A1: # | B1: Item needed from Omar (client) | C1: Why it matters | D1: Requested by | E1: Status | F1: Received on | G1: Notes
A2: 1 | B2: Logo variations (4 to 5) from client's logo team | C2: Needed for home header and brand direction | D2: Vinayak | E2: Not started
A3: 2 | B3: Colour and logo preferences | C3: Lets us check the palette against his taste | D3: Vinayak | E3: Not started | G3: Palette already chosen by Vinayak. Check fit, do not replace
A4: 3 | B4: Presentation PDFs and product details | C4: Source for product facts and copy | D4: Rayansh | E4: Not started | G4: Promised 19 Oct
A5: 4 | B5: 'How we work' document (water flow, filter stages) | C5: Builders page and installation page copy | D5: Rayansh | E5: Not started | G5: Use only claimable parts
A6: 5 | B6: Reference animation video | C6: Sets the style for the MP4 explainer | D6: Rayansh | E6: Not started | G6: Promised 22 Oct
A7: 6 | B7: Zero water wastage and 3LD: technical confirmation | C7: Claims on comparison and environment pages | D7: Vinayak | E7: Not started | G7: Do not publish until confirmed
A8: 7 | B8: Hyderabad community details and permission to name it | C8: Deployments strip | D8: Vinayak | E8: Not started | G8: Use placeholder until approved
A9: 8 | B9: Final brand name: Moya One or Moya1 | C9: Domain, logo, trademark | D9: Rayansh | E9: Not started | G9: Domain go-moya-one.com recommended
A10: 9 | B10: Confirmation of domain spelling and purchase approval | C10: Domain purchase | D10: Rayansh | E10: Not started
A11: 10 | B11: Monthly plan terms (minimum occupancy, guarantee) for builder pages | C11: Builders page content | D11: Vinayak | E11: Not started | G11: Not in phase 1 price list. Confirm if needed

Sheet Claims
A1: Claim | B1: Where it came from | C1: Status | D1: Action before publishing
A2: Zero water wastage (unlike RO, which wastes about as much as it delivers) | B2: Client, 19 Oct call | C2: To confirm | D2: Get written technical confirmation (C3)
A3: 3LD (zero liquid discharge) technology | B3: Client, 22 Oct call | C3: To confirm | D3: Do not publish until verified
A4: Patented technology | B4: Client said 'patented' on 19 Oct, then 'filed, not yet examined' on 22 Oct | C4: Do not use as stated | D4: Use 'patent filed' until granted (B7)
A5: Moya1 control-unit trademark | B5: Client, 22 Oct call | C5: Filed, not registered | D5: Use the TM symbol only, not the registered mark
A6: Hyderabad community, about 300 apartments, being installed | B6: Client, 19 Oct call | C6: To confirm | D6: Placeholder until client approves naming
A7: Deployed in India | B7: Client, 19 Oct call | C7: To confirm | D7: Show India only, marked to confirm
A8: UAE talks with two developers | B8: Client, 19 Oct call | C8: Do not publish | D8: Do not name developers or show logos
A9: Unlimited water on subscription | B9: Client, 19 Oct call | C9: To confirm | D9: Confirm plan terms before saying 'unlimited'
A10: Recharge from phone, like a mobile top-up | B10: Client, 19 Oct call; headline concept | C10: OK as concept | D10: App is not built. Show as concept
A11: Per-flat water-quality readings in app | B11: Client, 19 Oct call | C11: OK as concept | D11: Label all readings as sample data
A12: Best website in the world | B12: Rayansh on 22 Oct call | C12: Do not use | D12: Not a claim the site can make
... A14: Prices or rupee/dirham rates on site | B14: Earlier concept drafts | C14: Not in phase 1 | D14: Remove. Price terms are not public yet
